[2025-04-23T11:00:36.318+0000] {local_task_job_runner.py:123} INFO - ::group::Pre task execution logs
[2025-04-23T11:00:36.328+0000] {taskinstance.py:2614} INFO - Dependencies all met for dep_context=non-requeueable deps ti=<TaskInstance: dbt_transform.dbt_task_group.fact_weather_data_run manual__2025-04-23T10:57:01.209842+00:00 [queued]>
[2025-04-23T11:00:36.333+0000] {taskinstance.py:2614} INFO - Dependencies all met for dep_context=requeueable deps ti=<TaskInstance: dbt_transform.dbt_task_group.fact_weather_data_run manual__2025-04-23T10:57:01.209842+00:00 [queued]>
[2025-04-23T11:00:36.333+0000] {taskinstance.py:2867} INFO - Starting attempt 4 of 6
[2025-04-23T11:00:36.339+0000] {taskinstance.py:2890} INFO - Executing <Task(DbtRunLocalOperator): dbt_task_group.fact_weather_data_run> on 2025-04-23 10:57:01.209842+00:00
[2025-04-23T11:00:36.346+0000] {warnings.py:112} WARNING - /home/***/.local/lib/python3.12/site-packages/***/task/task_runner/standard_task_runner.py:70: DeprecationWarning: This process (pid=13996) is multi-threaded, use of fork() may lead to deadlocks in the child.
  pid = os.fork()

[2025-04-23T11:00:36.347+0000] {standard_task_runner.py:72} INFO - Started process 14030 to run task
[2025-04-23T11:00:36.347+0000] {standard_task_runner.py:104} INFO - Running: ['***', 'tasks', 'run', 'dbt_transform', 'dbt_task_group.fact_weather_data_run', 'manual__2025-04-23T10:57:01.209842+00:00', '--job-id', '322', '--raw', '--subdir', 'DAGS_FOLDER/dbtdag.py', '--cfg-path', '/tmp/tmpvv4l8pv4']
[2025-04-23T11:00:36.348+0000] {standard_task_runner.py:105} INFO - Job 322: Subtask dbt_task_group.fact_weather_data_run
[2025-04-23T11:00:36.370+0000] {task_command.py:467} INFO - Running <TaskInstance: dbt_transform.dbt_task_group.fact_weather_data_run manual__2025-04-23T10:57:01.209842+00:00 [running]> on host eb276ba0497d
[2025-04-23T11:00:36.410+0000] {taskinstance.py:3134} INFO - Exporting env vars: AIRFLOW_CTX_DAG_OWNER='***' AIRFLOW_CTX_DAG_ID='dbt_transform' AIRFLOW_CTX_TASK_ID='dbt_task_group.fact_weather_data_run' AIRFLOW_CTX_EXECUTION_DATE='2025-04-23T10:57:01.209842+00:00' AIRFLOW_CTX_TRY_NUMBER='4' AIRFLOW_CTX_DAG_RUN_ID='manual__2025-04-23T10:57:01.209842+00:00'
[2025-04-23T11:00:36.412+0000] {taskinstance.py:732} INFO - ::endgroup::
[2025-04-23T11:00:36.413+0000] {local.py:213} INFO - dbtRunner is available. Using dbtRunner for invoking dbt.
[2025-04-23T11:00:36.414+0000] {local.py:416} INFO - Cloning project to writable temp directory /tmp/tmpazkzdltr from /opt/airflow/dags/dbt/weather
[2025-04-23T11:00:36.414+0000] {local.py:427} INFO - Partial parse is enabled and the latest partial parse file is /tmp/cosmos/dbt_transform__dbt_task_group/target/partial_parse.msgpack
[2025-04-23T11:00:36.420+0000] {config.py:360} INFO - Profile caching is enable.
[2025-04-23T11:00:36.424+0000] {base.py:84} INFO - Retrieving connection 'postgres'
[2025-04-23T11:00:36.424+0000] {config.py:340} INFO - Profile found in cache using profile: /tmp/cosmos/profile/e6e13df970e8fe3ebb4d61c03236437e24a01a4909ada5aa9ec817ff39ff3ca3/profiles.yml.
[2025-04-23T11:00:36.427+0000] {runner.py:60} INFO - Trying to run dbtRunner with:
 ['deps', '--project-dir', '/tmp/tmpazkzdltr', '--profiles-dir', '/tmp/cosmos/profile/e6e13df970e8fe3ebb4d61c03236437e24a01a4909ada5aa9ec817ff39ff3ca3', '--profile', 'default', '--target', 'dev']
 in /tmp/tmpazkzdltr
[2025-04-23T11:00:36.434+0000] {logging_mixin.py:190} INFO - 11:00:36  Running with dbt=1.8.7
[2025-04-23T11:00:36.459+0000] {logging_mixin.py:190} INFO - 11:00:36  Installing dbt-labs/dbt_utils
[2025-04-23T11:00:37.261+0000] {logging_mixin.py:190} INFO - 11:00:37  Installed from version 0.9.6
[2025-04-23T11:00:37.261+0000] {logging_mixin.py:190} INFO - 11:00:37  Updated version available: 1.3.0
[2025-04-23T11:00:37.262+0000] {logging_mixin.py:190} INFO - 11:00:37
[2025-04-23T11:00:37.262+0000] {logging_mixin.py:190} INFO - 11:00:37  Updates available for packages: ['dbt-labs/dbt_utils']                 
Update your versions in packages.yml, then run dbt deps
[2025-04-23T11:00:38.200+0000] {runner.py:60} INFO - Trying to run dbtRunner with:
 ['run', '--models', 'fact_weather_data', '--project-dir', '/tmp/tmpazkzdltr', '--profiles-dir', '/tmp/cosmos/profile/e6e13df970e8fe3ebb4d61c03236437e24a01a4909ada5aa9ec817ff39ff3ca3', '--profile', 'default', '--target', 'dev']
 in /tmp/tmpazkzdltr
[2025-04-23T11:00:38.204+0000] {logging_mixin.py:190} INFO - 11:00:38  Running with dbt=1.8.7
[2025-04-23T11:00:38.226+0000] {logging_mixin.py:190} INFO - 11:00:38  Registered adapter: postgres=1.9.0
[2025-04-23T11:00:38.260+0000] {logging_mixin.py:190} INFO - 11:00:38  Unable to do partial parsing because profile has changed
[2025-04-23T11:00:38.738+0000] {logging_mixin.py:190} INFO - 11:00:38  Found 5 models, 626 macros
[2025-04-23T11:00:38.739+0000] {logging_mixin.py:190} INFO - 11:00:38
[2025-04-23T11:00:38.777+0000] {logging_mixin.py:190} INFO - 11:00:38  Concurrency: 1 threads (target='dev')
[2025-04-23T11:00:38.778+0000] {logging_mixin.py:190} INFO - 11:00:38
[2025-04-23T11:00:38.779+0000] {logging_mixin.py:190} INFO - 11:00:38  1 of 1 START sql table model transformed.fact_weather_data ..................... [RUN]
[2025-04-23T11:00:38.994+0000] {logging_mixin.py:190} INFO - 11:00:38  1 of 1 ERROR creating sql table model transformed.fact_weather_data ............ [ERROR in 0.21s]
[2025-04-23T11:00:39.000+0000] {logging_mixin.py:190} INFO - 11:00:39
[2025-04-23T11:00:39.000+0000] {logging_mixin.py:190} INFO - 11:00:39  Finished running 1 table model in 0 hours 0 minutes and 0.26 seconds (0.26s).
[2025-04-23T11:00:39.018+0000] {logging_mixin.py:190} INFO - 11:00:39
[2025-04-23T11:00:39.018+0000] {logging_mixin.py:190} INFO - 11:00:39  Completed with 1 error and 0 warnings:
[2025-04-23T11:00:39.019+0000] {logging_mixin.py:190} INFO - 11:00:39
[2025-04-23T11:00:39.019+0000] {logging_mixin.py:190} INFO - 11:00:39    Database Error in model fact_weather_data (models/marts/fact_weather_data.sql)
  column b.time does not exist
  LINE 38:     b."time"
               ^
  HINT:  Perhaps you meant to reference the column "b.name".
  compiled code at target/run/weather/models/marts/fact_weather_data.sql
[2025-04-23T11:00:39.019+0000] {logging_mixin.py:190} INFO - 11:00:39
[2025-04-23T11:00:39.019+0000] {logging_mixin.py:190} INFO - 11:00:39  Done. PASS=0 WARN=0 ERROR=1 SKIP=0 TOTAL=1
[2025-04-23T11:00:39.945+0000] {local.py:465} INFO - Inlets: []
[2025-04-23T11:00:39.945+0000] {local.py:466} INFO - Outlets: []
[2025-04-23T11:00:39.945+0000] {local.py:656} INFO - Assigning inlets/outlets with DatasetAlias
[2025-04-23T11:00:39.959+0000] {taskinstance.py:3313} ERROR - Task failed with exception
Traceback (most recent call last):
  File "/home/airflow/.local/lib/python3.12/site-packages/airflow/models/taskinstance.py", line 768, in _execute_task
    result = _execute_callable(context=context, **execute_callable_kwargs)
             ^^^^^^^^^^^^^^^^^^^^^^^^^^^^^^^^^^^^^^^^^^^^^^^^^^^^^^^^^^^^^
  File "/home/airflow/.local/lib/python3.12/site-packages/airflow/models/taskinstance.py", line 734, in _execute_callable
    return ExecutionCallableRunner(
           ^^^^^^^^^^^^^^^^^^^^^^^^
  File "/home/airflow/.local/lib/python3.12/site-packages/airflow/utils/operator_helpers.py", line 252, in run
    return self.func(*args, **kwargs)
           ^^^^^^^^^^^^^^^^^^^^^^^^^^
  File "/home/airflow/.local/lib/python3.12/site-packages/cosmos/operators/base.py", line 299, in execute
    self.build_and_run_cmd(context=context, cmd_flags=self.add_cmd_flags())
  File "/home/airflow/.local/lib/python3.12/site-packages/cosmos/operators/local.py", line 708, in build_and_run_cmd
    result = self.run_command(
             ^^^^^^^^^^^^^^^^^
  File "/home/airflow/.local/lib/python3.12/site-packages/cosmos/operators/local.py", line 556, in run_command
    self.handle_exception(result)
  File "/home/airflow/.local/lib/python3.12/site-packages/cosmos/operators/local.py", line 227, in handle_exception_dbt_runner
    return dbt_runner.handle_exception_if_needed(result)
           ^^^^^^^^^^^^^^^^^^^^^^^^^^^^^^^^^^^^^^^^^^^^^
  File "/home/airflow/.local/lib/python3.12/site-packages/cosmos/dbt/runner.py", line 113, in handle_exception_if_needed
    raise CosmosDbtRunError(f"dbt invocation completed with errors: {error_message}")
cosmos.exceptions.CosmosDbtRunError: dbt invocation completed with errors: fact_weather_data: Database Error in model fact_weather_data (models/marts/fact_weather_data.sql)
  column b.time does not exist
  LINE 38:     b."time"
               ^
  HINT:  Perhaps you meant to reference the column "b.name".
  compiled code at target/run/weather/models/marts/fact_weather_data.sql
[2025-04-23T11:00:39.964+0000] {taskinstance.py:1226} INFO - Marking task as UP_FOR_RETRY. dag_id=dbt_transform, task_id=dbt_task_group.fact_weather_data_run, run_id=manual__2025-04-23T10:57:01.209842+00:00, execution_date=20250423T105701, start_date=20250423T110036, end_date=20250423T110039
[2025-04-23T11:00:39.980+0000] {taskinstance.py:341} INFO - ::group::Post task execution logs
[2025-04-23T11:00:39.980+0000] {standard_task_runner.py:124} ERROR - Failed to execute job 322 for task dbt_task_group.fact_weather_data_run (dbt invocation completed with errors: fact_weather_data: Database Error in model fact_weather_data (models/marts/fact_weather_data.sql)
  column b.time does not exist
  LINE 38:     b."time"
               ^
  HINT:  Perhaps you meant to reference the column "b.name".
  compiled code at target/run/weather/models/marts/fact_weather_data.sql; 14030)
Traceback (most recent call last):
  File "/home/airflow/.local/lib/python3.12/site-packages/airflow/task/task_runner/standard_task_runner.py", line 117, in _start_by_fork
    ret = args.func(args, dag=self.dag)
          ^^^^^^^^^^^^^^^^^^^^^^^^^^^^^
  File "/home/airflow/.local/lib/python3.12/site-packages/airflow/cli/cli_config.py", line 49, in command
    return func(*args, **kwargs)
           ^^^^^^^^^^^^^^^^^^^^^
  File "/home/airflow/.local/lib/python3.12/site-packages/airflow/utils/cli.py", line 116, in wrapper
    return f(*args, **kwargs)
           ^^^^^^^^^^^^^^^^^^
  File "/home/airflow/.local/lib/python3.12/site-packages/airflow/cli/commands/task_command.py", line 483, in task_run
    task_return_code = _run_task_by_selected_method(args, _dag, ti)
                       ^^^^^^^^^^^^^^^^^^^^^^^^^^^^^^^^^^^^^^^^^^^^
  File "/home/airflow/.local/lib/python3.12/site-packages/airflow/cli/commands/task_command.py", line 256, in _run_task_by_selected_method
    return _run_raw_task(args, ti)
           ^^^^^^^^^^^^^^^^^^^^^^^
  File "/home/airflow/.local/lib/python3.12/site-packages/airflow/cli/commands/task_command.py", line 341, in _run_raw_task
    return ti._run_raw_task(
           ^^^^^^^^^^^^^^^^^
  File "/home/airflow/.local/lib/python3.12/site-packages/airflow/utils/session.py", line 97, in wrapper
    return func(*args, session=session, **kwargs)
           ^^^^^^^^^^^^^^^^^^^^^^^^^^^^^^^^^^^^^^
  File "/home/airflow/.local/lib/python3.12/site-packages/airflow/models/taskinstance.py", line 3006, in _run_raw_task
    return _run_raw_task(
           ^^^^^^^^^^^^^^
  File "/home/airflow/.local/lib/python3.12/site-packages/airflow/models/taskinstance.py", line 274, in _run_raw_task
    TaskInstance._execute_task_with_callbacks(
  File "/home/airflow/.local/lib/python3.12/site-packages/airflow/models/taskinstance.py", line 3161, in _execute_task_with_callbacks
    result = self._execute_task(context, task_orig)
             ^^^^^^^^^^^^^^^^^^^^^^^^^^^^^^^^^^^^^^
  File "/home/airflow/.local/lib/python3.12/site-packages/airflow/models/taskinstance.py", line 3185, in _execute_task
    return _execute_task(self, context, task_orig)
           ^^^^^^^^^^^^^^^^^^^^^^^^^^^^^^^^^^^^^^^
  File "/home/airflow/.local/lib/python3.12/site-packages/airflow/models/taskinstance.py", line 768, in _execute_task
    result = _execute_callable(context=context, **execute_callable_kwargs)
             ^^^^^^^^^^^^^^^^^^^^^^^^^^^^^^^^^^^^^^^^^^^^^^^^^^^^^^^^^^^^^
  File "/home/airflow/.local/lib/python3.12/site-packages/airflow/models/taskinstance.py", line 734, in _execute_callable
    return ExecutionCallableRunner(
           ^^^^^^^^^^^^^^^^^^^^^^^^
  File "/home/airflow/.local/lib/python3.12/site-packages/airflow/utils/operator_helpers.py", line 252, in run
    return self.func(*args, **kwargs)
           ^^^^^^^^^^^^^^^^^^^^^^^^^^
  File "/home/airflow/.local/lib/python3.12/site-packages/cosmos/operators/base.py", line 299, in execute
    self.build_and_run_cmd(context=context, cmd_flags=self.add_cmd_flags())
  File "/home/airflow/.local/lib/python3.12/site-packages/cosmos/operators/local.py", line 708, in build_and_run_cmd
    result = self.run_command(
             ^^^^^^^^^^^^^^^^^
  File "/home/airflow/.local/lib/python3.12/site-packages/cosmos/operators/local.py", line 556, in run_command
    self.handle_exception(result)
  File "/home/airflow/.local/lib/python3.12/site-packages/cosmos/operators/local.py", line 227, in handle_exception_dbt_runner
    return dbt_runner.handle_exception_if_needed(result)
           ^^^^^^^^^^^^^^^^^^^^^^^^^^^^^^^^^^^^^^^^^^^^^
  File "/home/airflow/.local/lib/python3.12/site-packages/cosmos/dbt/runner.py", line 113, in handle_exception_if_needed
    raise CosmosDbtRunError(f"dbt invocation completed with errors: {error_message}")
cosmos.exceptions.CosmosDbtRunError: dbt invocation completed with errors: fact_weather_data: Database Error in model fact_weather_data (models/marts/fact_weather_data.sql)
  column b.time does not exist
  LINE 38:     b."time"
               ^
  HINT:  Perhaps you meant to reference the column "b.name".
  compiled code at target/run/weather/models/marts/fact_weather_data.sql
[2025-04-23T11:00:40.007+0000] {local_task_job_runner.py:266} INFO - Task exited with return code 1
[2025-04-23T11:00:40.019+0000] {taskinstance.py:3901} INFO - 0 downstream tasks scheduled from follow-on schedule check
[2025-04-23T11:00:40.020+0000] {local_task_job_runner.py:245} INFO - ::endgroup::
