[2025-04-23T09:33:13.264+0000] {local_task_job_runner.py:123} INFO - ::group::Pre task execution logs
[2025-04-23T09:33:13.275+0000] {taskinstance.py:2614} INFO - Dependencies all met for dep_context=non-requeueable deps ti=<TaskInstance: fetch_weather_data_daily.load_backfill_data_0 manual__2025-04-23T09:31:00.792292+00:00 [queued]>
[2025-04-23T09:33:13.279+0000] {taskinstance.py:2614} INFO - Dependencies all met for dep_context=requeueable deps ti=<TaskInstance: fetch_weather_data_daily.load_backfill_data_0 manual__2025-04-23T09:31:00.792292+00:00 [queued]>
[2025-04-23T09:33:13.279+0000] {taskinstance.py:2867} INFO - Starting attempt 1 of 2
[2025-04-23T09:33:13.286+0000] {taskinstance.py:2890} INFO - Executing <Task(_PythonDecoratedOperator): load_backfill_data_0> on 2025-04-23 09:31:00.792292+00:00
[2025-04-23T09:33:13.292+0000] {warnings.py:112} WARNING - /home/***/.local/lib/python3.12/site-packages/***/task/task_runner/standard_task_runner.py:70: DeprecationWarning: This process (pid=5456) is multi-threaded, use of fork() may lead to deadlocks in the child.
  pid = os.fork()

[2025-04-23T09:33:13.293+0000] {standard_task_runner.py:72} INFO - Started process 5466 to run task
[2025-04-23T09:33:13.293+0000] {standard_task_runner.py:104} INFO - Running: ['***', 'tasks', 'run', 'fetch_weather_data_daily', 'load_backfill_data_0', 'manual__2025-04-23T09:31:00.792292+00:00', '--job-id', '231', '--raw', '--subdir', 'DAGS_FOLDER/el_daily.py', '--cfg-path', '/tmp/tmpk_djvbag']
[2025-04-23T09:33:13.294+0000] {standard_task_runner.py:105} INFO - Job 231: Subtask load_backfill_data_0
[2025-04-23T09:33:13.318+0000] {task_command.py:467} INFO - Running <TaskInstance: fetch_weather_data_daily.load_backfill_data_0 manual__2025-04-23T09:31:00.792292+00:00 [running]> on host eb276ba0497d
[2025-04-23T09:33:13.417+0000] {taskinstance.py:3134} INFO - Exporting env vars: AIRFLOW_CTX_DAG_OWNER='***' AIRFLOW_CTX_DAG_ID='fetch_weather_data_daily' AIRFLOW_CTX_TASK_ID='load_backfill_data_0' AIRFLOW_CTX_EXECUTION_DATE='2025-04-23T09:31:00.792292+00:00' AIRFLOW_CTX_TRY_NUMBER='1' AIRFLOW_CTX_DAG_RUN_ID='manual__2025-04-23T09:31:00.792292+00:00'
[2025-04-23T09:33:13.418+0000] {taskinstance.py:732} INFO - ::endgroup::
[2025-04-23T09:33:13.438+0000] {taskinstance.py:3313} ERROR - Task failed with exception
Traceback (most recent call last):
  File "/home/airflow/.local/lib/python3.12/site-packages/sqlalchemy/engine/base.py", line 1910, in _execute_context
    self.dialect.do_execute(
  File "/home/airflow/.local/lib/python3.12/site-packages/sqlalchemy/engine/default.py", line 736, in do_execute
    cursor.execute(statement, parameters)
psycopg2.errors.UniqueViolation: duplicate key value violates unique constraint "pg_type_typname_nsp_index"
DETAIL:  Key (typname, typnamespace)=(weather_daily, 2200) already exists.


The above exception was the direct cause of the following exception:

Traceback (most recent call last):
  File "/home/airflow/.local/lib/python3.12/site-packages/airflow/models/taskinstance.py", line 768, in _execute_task
    result = _execute_callable(context=context, **execute_callable_kwargs)
             ^^^^^^^^^^^^^^^^^^^^^^^^^^^^^^^^^^^^^^^^^^^^^^^^^^^^^^^^^^^^^
  File "/home/airflow/.local/lib/python3.12/site-packages/airflow/models/taskinstance.py", line 734, in _execute_callable
    return ExecutionCallableRunner(
           ^^^^^^^^^^^^^^^^^^^^^^^^
  File "/home/airflow/.local/lib/python3.12/site-packages/airflow/utils/operator_helpers.py", line 252, in run
    return self.func(*args, **kwargs)
           ^^^^^^^^^^^^^^^^^^^^^^^^^^
  File "/home/airflow/.local/lib/python3.12/site-packages/airflow/models/baseoperator.py", line 424, in wrapper
    return func(self, *args, **kwargs)
           ^^^^^^^^^^^^^^^^^^^^^^^^^^^
  File "/home/airflow/.local/lib/python3.12/site-packages/airflow/decorators/base.py", line 266, in execute
    return_value = super().execute(context)
                   ^^^^^^^^^^^^^^^^^^^^^^^^
  File "/home/airflow/.local/lib/python3.12/site-packages/airflow/models/baseoperator.py", line 424, in wrapper
    return func(self, *args, **kwargs)
           ^^^^^^^^^^^^^^^^^^^^^^^^^^^
  File "/home/airflow/.local/lib/python3.12/site-packages/airflow/operators/python.py", line 238, in execute
    return_value = self.execute_callable()
                   ^^^^^^^^^^^^^^^^^^^^^^^
  File "/home/airflow/.local/lib/python3.12/site-packages/airflow/operators/python.py", line 256, in execute_callable
    return runner.run(*self.op_args, **self.op_kwargs)
           ^^^^^^^^^^^^^^^^^^^^^^^^^^^^^^^^^^^^^^^^^^^
  File "/home/airflow/.local/lib/python3.12/site-packages/airflow/utils/operator_helpers.py", line 252, in run
    return self.func(*args, **kwargs)
           ^^^^^^^^^^^^^^^^^^^^^^^^^^
  File "/opt/airflow/dags/el_daily.py", line 226, in load_to_postgres
    df.to_sql('weather_daily', con=engine, if_exists='append', index=False)
  File "/home/airflow/.local/lib/python3.12/site-packages/pandas/util/_decorators.py", line 333, in wrapper
    return func(*args, **kwargs)
           ^^^^^^^^^^^^^^^^^^^^^
  File "/home/airflow/.local/lib/python3.12/site-packages/pandas/core/generic.py", line 3008, in to_sql
    return sql.to_sql(
           ^^^^^^^^^^^
  File "/home/airflow/.local/lib/python3.12/site-packages/pandas/io/sql.py", line 788, in to_sql
    return pandas_sql.to_sql(
           ^^^^^^^^^^^^^^^^^^
  File "/home/airflow/.local/lib/python3.12/site-packages/pandas/io/sql.py", line 1948, in to_sql
    table = self.prep_table(
            ^^^^^^^^^^^^^^^^
  File "/home/airflow/.local/lib/python3.12/site-packages/pandas/io/sql.py", line 1852, in prep_table
    table.create()
  File "/home/airflow/.local/lib/python3.12/site-packages/pandas/io/sql.py", line 936, in create
    self._execute_create()
  File "/home/airflow/.local/lib/python3.12/site-packages/pandas/io/sql.py", line 922, in _execute_create
    self.table.create(bind=self.pd_sql.con)
  File "/home/airflow/.local/lib/python3.12/site-packages/sqlalchemy/sql/schema.py", line 962, in create
    bind._run_ddl_visitor(ddl.SchemaGenerator, self, checkfirst=checkfirst)
  File "/home/airflow/.local/lib/python3.12/site-packages/sqlalchemy/engine/base.py", line 2221, in _run_ddl_visitor
    visitorcallable(self.dialect, self, **kwargs).traverse_single(element)
  File "/home/airflow/.local/lib/python3.12/site-packages/sqlalchemy/sql/visitors.py", line 524, in traverse_single
    return meth(obj, **kw)
           ^^^^^^^^^^^^^^^
  File "/home/airflow/.local/lib/python3.12/site-packages/sqlalchemy/sql/ddl.py", line 899, in visit_table
    self.connection.execute(
  File "/home/airflow/.local/lib/python3.12/site-packages/sqlalchemy/engine/base.py", line 1385, in execute
    return meth(self, multiparams, params, _EMPTY_EXECUTION_OPTS)
           ^^^^^^^^^^^^^^^^^^^^^^^^^^^^^^^^^^^^^^^^^^^^^^^^^^^^^^
  File "/home/airflow/.local/lib/python3.12/site-packages/sqlalchemy/sql/ddl.py", line 80, in _execute_on_connection
    return connection._execute_ddl(
           ^^^^^^^^^^^^^^^^^^^^^^^^
  File "/home/airflow/.local/lib/python3.12/site-packages/sqlalchemy/engine/base.py", line 1477, in _execute_ddl
    ret = self._execute_context(
          ^^^^^^^^^^^^^^^^^^^^^^
  File "/home/airflow/.local/lib/python3.12/site-packages/sqlalchemy/engine/base.py", line 1953, in _execute_context
    self._handle_dbapi_exception(
  File "/home/airflow/.local/lib/python3.12/site-packages/sqlalchemy/engine/base.py", line 2134, in _handle_dbapi_exception
    util.raise_(
  File "/home/airflow/.local/lib/python3.12/site-packages/sqlalchemy/util/compat.py", line 211, in raise_
    raise exception
  File "/home/airflow/.local/lib/python3.12/site-packages/sqlalchemy/engine/base.py", line 1910, in _execute_context
    self.dialect.do_execute(
  File "/home/airflow/.local/lib/python3.12/site-packages/sqlalchemy/engine/default.py", line 736, in do_execute
    cursor.execute(statement, parameters)
sqlalchemy.exc.IntegrityError: (psycopg2.errors.UniqueViolation) duplicate key value violates unique constraint "pg_type_typname_nsp_index"
DETAIL:  Key (typname, typnamespace)=(weather_daily, 2200) already exists.

[SQL: 
CREATE TABLE weather_daily (
	name TEXT, 
	region TEXT, 
	country TEXT, 
	lat FLOAT(53), 
	lon FLOAT(53), 
	tz_id TEXT, 
	localtime_epoch BIGINT, 
	"localtime" TEXT, 
	time TEXT, 
	temp_c FLOAT(53), 
	temp_f FLOAT(53), 
	condition_text TEXT, 
	condition_icon TEXT, 
	wind_mph FLOAT(53), 
	wind_kph FLOAT(53), 
	wind_degree BIGINT, 
	wind_dir TEXT, 
	pressure_mb FLOAT(53), 
	pressure_in FLOAT(53), 
	precip_mm FLOAT(53), 
	precip_in FLOAT(53), 
	snow_cm FLOAT(53), 
	humidity BIGINT, 
	cloud BIGINT, 
	feelslike_c FLOAT(53), 
	feelslike_f FLOAT(53), 
	windchill_c FLOAT(53), 
	windchill_f FLOAT(53), 
	heatindex_c FLOAT(53), 
	heatindex_f FLOAT(53), 
	dewpoint_c FLOAT(53), 
	dewpoint_f FLOAT(53), 
	will_it_rain BIGINT, 
	chance_of_rain BIGINT, 
	will_it_snow BIGINT, 
	chance_of_snow BIGINT, 
	vis_km FLOAT(53), 
	vis_miles FLOAT(53), 
	gust_mph FLOAT(53), 
	gust_kph FLOAT(53), 
	uv FLOAT(53)
)

]
(Background on this error at: https://sqlalche.me/e/14/gkpj)
[2025-04-23T09:33:13.449+0000] {taskinstance.py:1226} INFO - Marking task as UP_FOR_RETRY. dag_id=fetch_weather_data_daily, task_id=load_backfill_data_0, run_id=manual__2025-04-23T09:31:00.792292+00:00, execution_date=20250423T093100, start_date=20250423T093313, end_date=20250423T093313
[2025-04-23T09:33:13.463+0000] {taskinstance.py:341} INFO - ::group::Post task execution logs
[2025-04-23T09:33:13.463+0000] {standard_task_runner.py:124} ERROR - Failed to execute job 231 for task load_backfill_data_0 ((psycopg2.errors.UniqueViolation) duplicate key value violates unique constraint "pg_type_typname_nsp_index"
DETAIL:  Key (typname, typnamespace)=(weather_daily, 2200) already exists.

[SQL: 
CREATE TABLE weather_daily (
	name TEXT, 
	region TEXT, 
	country TEXT, 
	lat FLOAT(53), 
	lon FLOAT(53), 
	tz_id TEXT, 
	localtime_epoch BIGINT, 
	"localtime" TEXT, 
	time TEXT, 
	temp_c FLOAT(53), 
	temp_f FLOAT(53), 
	condition_text TEXT, 
	condition_icon TEXT, 
	wind_mph FLOAT(53), 
	wind_kph FLOAT(53), 
	wind_degree BIGINT, 
	wind_dir TEXT, 
	pressure_mb FLOAT(53), 
	pressure_in FLOAT(53), 
	precip_mm FLOAT(53), 
	precip_in FLOAT(53), 
	snow_cm FLOAT(53), 
	humidity BIGINT, 
	cloud BIGINT, 
	feelslike_c FLOAT(53), 
	feelslike_f FLOAT(53), 
	windchill_c FLOAT(53), 
	windchill_f FLOAT(53), 
	heatindex_c FLOAT(53), 
	heatindex_f FLOAT(53), 
	dewpoint_c FLOAT(53), 
	dewpoint_f FLOAT(53), 
	will_it_rain BIGINT, 
	chance_of_rain BIGINT, 
	will_it_snow BIGINT, 
	chance_of_snow BIGINT, 
	vis_km FLOAT(53), 
	vis_miles FLOAT(53), 
	gust_mph FLOAT(53), 
	gust_kph FLOAT(53), 
	uv FLOAT(53)
)

]
(Background on this error at: https://sqlalche.me/e/14/gkpj); 5466)
Traceback (most recent call last):
  File "/home/airflow/.local/lib/python3.12/site-packages/sqlalchemy/engine/base.py", line 1910, in _execute_context
    self.dialect.do_execute(
  File "/home/airflow/.local/lib/python3.12/site-packages/sqlalchemy/engine/default.py", line 736, in do_execute
    cursor.execute(statement, parameters)
psycopg2.errors.UniqueViolation: duplicate key value violates unique constraint "pg_type_typname_nsp_index"
DETAIL:  Key (typname, typnamespace)=(weather_daily, 2200) already exists.


The above exception was the direct cause of the following exception:

Traceback (most recent call last):
  File "/home/airflow/.local/lib/python3.12/site-packages/airflow/task/task_runner/standard_task_runner.py", line 117, in _start_by_fork
    ret = args.func(args, dag=self.dag)
          ^^^^^^^^^^^^^^^^^^^^^^^^^^^^^
  File "/home/airflow/.local/lib/python3.12/site-packages/airflow/cli/cli_config.py", line 49, in command
    return func(*args, **kwargs)
           ^^^^^^^^^^^^^^^^^^^^^
  File "/home/airflow/.local/lib/python3.12/site-packages/airflow/utils/cli.py", line 116, in wrapper
    return f(*args, **kwargs)
           ^^^^^^^^^^^^^^^^^^
  File "/home/airflow/.local/lib/python3.12/site-packages/airflow/cli/commands/task_command.py", line 483, in task_run
    task_return_code = _run_task_by_selected_method(args, _dag, ti)
                       ^^^^^^^^^^^^^^^^^^^^^^^^^^^^^^^^^^^^^^^^^^^^
  File "/home/airflow/.local/lib/python3.12/site-packages/airflow/cli/commands/task_command.py", line 256, in _run_task_by_selected_method
    return _run_raw_task(args, ti)
           ^^^^^^^^^^^^^^^^^^^^^^^
  File "/home/airflow/.local/lib/python3.12/site-packages/airflow/cli/commands/task_command.py", line 341, in _run_raw_task
    return ti._run_raw_task(
           ^^^^^^^^^^^^^^^^^
  File "/home/airflow/.local/lib/python3.12/site-packages/airflow/utils/session.py", line 97, in wrapper
    return func(*args, session=session, **kwargs)
           ^^^^^^^^^^^^^^^^^^^^^^^^^^^^^^^^^^^^^^
  File "/home/airflow/.local/lib/python3.12/site-packages/airflow/models/taskinstance.py", line 3006, in _run_raw_task
    return _run_raw_task(
           ^^^^^^^^^^^^^^
  File "/home/airflow/.local/lib/python3.12/site-packages/airflow/models/taskinstance.py", line 274, in _run_raw_task
    TaskInstance._execute_task_with_callbacks(
  File "/home/airflow/.local/lib/python3.12/site-packages/airflow/models/taskinstance.py", line 3161, in _execute_task_with_callbacks
    result = self._execute_task(context, task_orig)
             ^^^^^^^^^^^^^^^^^^^^^^^^^^^^^^^^^^^^^^
  File "/home/airflow/.local/lib/python3.12/site-packages/airflow/models/taskinstance.py", line 3185, in _execute_task
    return _execute_task(self, context, task_orig)
           ^^^^^^^^^^^^^^^^^^^^^^^^^^^^^^^^^^^^^^^
  File "/home/airflow/.local/lib/python3.12/site-packages/airflow/models/taskinstance.py", line 768, in _execute_task
    result = _execute_callable(context=context, **execute_callable_kwargs)
             ^^^^^^^^^^^^^^^^^^^^^^^^^^^^^^^^^^^^^^^^^^^^^^^^^^^^^^^^^^^^^
  File "/home/airflow/.local/lib/python3.12/site-packages/airflow/models/taskinstance.py", line 734, in _execute_callable
    return ExecutionCallableRunner(
           ^^^^^^^^^^^^^^^^^^^^^^^^
  File "/home/airflow/.local/lib/python3.12/site-packages/airflow/utils/operator_helpers.py", line 252, in run
    return self.func(*args, **kwargs)
           ^^^^^^^^^^^^^^^^^^^^^^^^^^
  File "/home/airflow/.local/lib/python3.12/site-packages/airflow/models/baseoperator.py", line 424, in wrapper
    return func(self, *args, **kwargs)
           ^^^^^^^^^^^^^^^^^^^^^^^^^^^
  File "/home/airflow/.local/lib/python3.12/site-packages/airflow/decorators/base.py", line 266, in execute
    return_value = super().execute(context)
                   ^^^^^^^^^^^^^^^^^^^^^^^^
  File "/home/airflow/.local/lib/python3.12/site-packages/airflow/models/baseoperator.py", line 424, in wrapper
    return func(self, *args, **kwargs)
           ^^^^^^^^^^^^^^^^^^^^^^^^^^^
  File "/home/airflow/.local/lib/python3.12/site-packages/airflow/operators/python.py", line 238, in execute
    return_value = self.execute_callable()
                   ^^^^^^^^^^^^^^^^^^^^^^^
  File "/home/airflow/.local/lib/python3.12/site-packages/airflow/operators/python.py", line 256, in execute_callable
    return runner.run(*self.op_args, **self.op_kwargs)
           ^^^^^^^^^^^^^^^^^^^^^^^^^^^^^^^^^^^^^^^^^^^
  File "/home/airflow/.local/lib/python3.12/site-packages/airflow/utils/operator_helpers.py", line 252, in run
    return self.func(*args, **kwargs)
           ^^^^^^^^^^^^^^^^^^^^^^^^^^
  File "/opt/airflow/dags/el_daily.py", line 226, in load_to_postgres
    df.to_sql('weather_daily', con=engine, if_exists='append', index=False)
  File "/home/airflow/.local/lib/python3.12/site-packages/pandas/util/_decorators.py", line 333, in wrapper
    return func(*args, **kwargs)
           ^^^^^^^^^^^^^^^^^^^^^
  File "/home/airflow/.local/lib/python3.12/site-packages/pandas/core/generic.py", line 3008, in to_sql
    return sql.to_sql(
           ^^^^^^^^^^^
  File "/home/airflow/.local/lib/python3.12/site-packages/pandas/io/sql.py", line 788, in to_sql
    return pandas_sql.to_sql(
           ^^^^^^^^^^^^^^^^^^
  File "/home/airflow/.local/lib/python3.12/site-packages/pandas/io/sql.py", line 1948, in to_sql
    table = self.prep_table(
            ^^^^^^^^^^^^^^^^
  File "/home/airflow/.local/lib/python3.12/site-packages/pandas/io/sql.py", line 1852, in prep_table
    table.create()
  File "/home/airflow/.local/lib/python3.12/site-packages/pandas/io/sql.py", line 936, in create
    self._execute_create()
  File "/home/airflow/.local/lib/python3.12/site-packages/pandas/io/sql.py", line 922, in _execute_create
    self.table.create(bind=self.pd_sql.con)
  File "/home/airflow/.local/lib/python3.12/site-packages/sqlalchemy/sql/schema.py", line 962, in create
    bind._run_ddl_visitor(ddl.SchemaGenerator, self, checkfirst=checkfirst)
  File "/home/airflow/.local/lib/python3.12/site-packages/sqlalchemy/engine/base.py", line 2221, in _run_ddl_visitor
    visitorcallable(self.dialect, self, **kwargs).traverse_single(element)
  File "/home/airflow/.local/lib/python3.12/site-packages/sqlalchemy/sql/visitors.py", line 524, in traverse_single
    return meth(obj, **kw)
           ^^^^^^^^^^^^^^^
  File "/home/airflow/.local/lib/python3.12/site-packages/sqlalchemy/sql/ddl.py", line 899, in visit_table
    self.connection.execute(
  File "/home/airflow/.local/lib/python3.12/site-packages/sqlalchemy/engine/base.py", line 1385, in execute
    return meth(self, multiparams, params, _EMPTY_EXECUTION_OPTS)
           ^^^^^^^^^^^^^^^^^^^^^^^^^^^^^^^^^^^^^^^^^^^^^^^^^^^^^^
  File "/home/airflow/.local/lib/python3.12/site-packages/sqlalchemy/sql/ddl.py", line 80, in _execute_on_connection
    return connection._execute_ddl(
           ^^^^^^^^^^^^^^^^^^^^^^^^
  File "/home/airflow/.local/lib/python3.12/site-packages/sqlalchemy/engine/base.py", line 1477, in _execute_ddl
    ret = self._execute_context(
          ^^^^^^^^^^^^^^^^^^^^^^
  File "/home/airflow/.local/lib/python3.12/site-packages/sqlalchemy/engine/base.py", line 1953, in _execute_context
    self._handle_dbapi_exception(
  File "/home/airflow/.local/lib/python3.12/site-packages/sqlalchemy/engine/base.py", line 2134, in _handle_dbapi_exception
    util.raise_(
  File "/home/airflow/.local/lib/python3.12/site-packages/sqlalchemy/util/compat.py", line 211, in raise_
    raise exception
  File "/home/airflow/.local/lib/python3.12/site-packages/sqlalchemy/engine/base.py", line 1910, in _execute_context
    self.dialect.do_execute(
  File "/home/airflow/.local/lib/python3.12/site-packages/sqlalchemy/engine/default.py", line 736, in do_execute
    cursor.execute(statement, parameters)
sqlalchemy.exc.IntegrityError: (psycopg2.errors.UniqueViolation) duplicate key value violates unique constraint "pg_type_typname_nsp_index"
DETAIL:  Key (typname, typnamespace)=(weather_daily, 2200) already exists.

[SQL: 
CREATE TABLE weather_daily (
	name TEXT, 
	region TEXT, 
	country TEXT, 
	lat FLOAT(53), 
	lon FLOAT(53), 
	tz_id TEXT, 
	localtime_epoch BIGINT, 
	"localtime" TEXT, 
	time TEXT, 
	temp_c FLOAT(53), 
	temp_f FLOAT(53), 
	condition_text TEXT, 
	condition_icon TEXT, 
	wind_mph FLOAT(53), 
	wind_kph FLOAT(53), 
	wind_degree BIGINT, 
	wind_dir TEXT, 
	pressure_mb FLOAT(53), 
	pressure_in FLOAT(53), 
	precip_mm FLOAT(53), 
	precip_in FLOAT(53), 
	snow_cm FLOAT(53), 
	humidity BIGINT, 
	cloud BIGINT, 
	feelslike_c FLOAT(53), 
	feelslike_f FLOAT(53), 
	windchill_c FLOAT(53), 
	windchill_f FLOAT(53), 
	heatindex_c FLOAT(53), 
	heatindex_f FLOAT(53), 
	dewpoint_c FLOAT(53), 
	dewpoint_f FLOAT(53), 
	will_it_rain BIGINT, 
	chance_of_rain BIGINT, 
	will_it_snow BIGINT, 
	chance_of_snow BIGINT, 
	vis_km FLOAT(53), 
	vis_miles FLOAT(53), 
	gust_mph FLOAT(53), 
	gust_kph FLOAT(53), 
	uv FLOAT(53)
)

]
(Background on this error at: https://sqlalche.me/e/14/gkpj)
[2025-04-23T09:33:13.506+0000] {local_task_job_runner.py:266} INFO - Task exited with return code 1
[2025-04-23T09:33:13.519+0000] {taskinstance.py:3901} INFO - 0 downstream tasks scheduled from follow-on schedule check
[2025-04-23T09:33:13.520+0000] {local_task_job_runner.py:245} INFO - ::endgroup::
