[2025-04-23T06:13:42.080+0000] {local_task_job_runner.py:123} INFO - ::group::Pre task execution logs
[2025-04-23T06:13:42.090+0000] {taskinstance.py:2614} INFO - Dependencies all met for dep_context=non-requeueable deps ti=<TaskInstance: fetch_weather_data.load_to_postgres manual__2025-04-23T05:59:57.139793+00:00 [queued]>
[2025-04-23T06:13:42.094+0000] {taskinstance.py:2614} INFO - Dependencies all met for dep_context=requeueable deps ti=<TaskInstance: fetch_weather_data.load_to_postgres manual__2025-04-23T05:59:57.139793+00:00 [queued]>
[2025-04-23T06:13:42.094+0000] {taskinstance.py:2867} INFO - Starting attempt 5 of 6
[2025-04-23T06:13:42.100+0000] {taskinstance.py:2890} INFO - Executing <Task(_PythonDecoratedOperator): load_to_postgres> on 2025-04-23 05:59:57.139793+00:00
[2025-04-23T06:13:42.106+0000] {warnings.py:112} WARNING - /home/***/.local/lib/python3.12/site-packages/***/task/task_runner/standard_task_runner.py:70: DeprecationWarning: This process (pid=8458) is multi-threaded, use of fork() may lead to deadlocks in the child.
  pid = os.fork()

[2025-04-23T06:13:42.106+0000] {standard_task_runner.py:72} INFO - Started process 8460 to run task
[2025-04-23T06:13:42.107+0000] {standard_task_runner.py:104} INFO - Running: ['***', 'tasks', 'run', 'fetch_weather_data', 'load_to_postgres', 'manual__2025-04-23T05:59:57.139793+00:00', '--job-id', '49', '--raw', '--subdir', 'DAGS_FOLDER/el.py', '--cfg-path', '/tmp/tmp5nw5dujy']
[2025-04-23T06:13:42.108+0000] {standard_task_runner.py:105} INFO - Job 49: Subtask load_to_postgres
[2025-04-23T06:13:42.128+0000] {task_command.py:467} INFO - Running <TaskInstance: fetch_weather_data.load_to_postgres manual__2025-04-23T05:59:57.139793+00:00 [running]> on host eb276ba0497d
[2025-04-23T06:13:42.200+0000] {taskinstance.py:3134} INFO - Exporting env vars: AIRFLOW_CTX_DAG_OWNER='***' AIRFLOW_CTX_DAG_ID='fetch_weather_data' AIRFLOW_CTX_TASK_ID='load_to_postgres' AIRFLOW_CTX_EXECUTION_DATE='2025-04-23T05:59:57.139793+00:00' AIRFLOW_CTX_TRY_NUMBER='5' AIRFLOW_CTX_DAG_RUN_ID='manual__2025-04-23T05:59:57.139793+00:00'
[2025-04-23T06:13:42.201+0000] {taskinstance.py:732} INFO - ::endgroup::
[2025-04-23T06:13:42.206+0000] {base.py:84} INFO - Retrieving connection 'postgres'
[2025-04-23T06:13:42.235+0000] {el.py:176} ERROR - Error inserting data into PostgreSQL: syntax error at or near "localtime"
LINE 3: ..._name, country, lat, lon, tz_id, localtime_epoch, localtime,...
                                                             ^

[2025-04-23T06:13:42.235+0000] {python.py:240} INFO - Done. Returned value was: None
[2025-04-23T06:13:42.239+0000] {taskinstance.py:341} INFO - ::group::Post task execution logs
[2025-04-23T06:13:42.239+0000] {taskinstance.py:353} INFO - Marking task as SUCCESS. dag_id=fetch_weather_data, task_id=load_to_postgres, run_id=manual__2025-04-23T05:59:57.139793+00:00, execution_date=20250423T055957, start_date=20250423T061342, end_date=20250423T061342
[2025-04-23T06:13:42.280+0000] {local_task_job_runner.py:266} INFO - Task exited with return code 0
[2025-04-23T06:13:42.288+0000] {taskinstance.py:3901} INFO - 0 downstream tasks scheduled from follow-on schedule check
[2025-04-23T06:13:42.288+0000] {local_task_job_runner.py:245} INFO - ::endgroup::
